Workbook
Name Ctr_AllManagers: Lists!$B$1:$B$75
Name Ctr_AmitChakraborty: Lists!$C$1:$C$11
Name Ctr_Barna: Lists!$D$1:$D$12
Name Ctr_BhargavChalla: Lists!$E$1:$E$7
Name Ctr_GagandeepSinghSachar: Lists!$F$1:$F$11
Name Ctr_MahaboobBasha: Lists!$G$1:$G$4
Name Ctr_Phani: Lists!$H$1:$H$15
Name Ctr_RaghavenderRao: Lists!$I$1:$I$4
Name Ctr_SJakir: Lists!$J$1:$J$16
Name Ctr_SanjayKumarTarai: Lists!$K$1:$K$3

Sheet Dashboard
A1: Unannounced Monthly Centre Visit — Interactive Dashboard
A3: Second Level Manager field audits · 1 Jul 2026–23 Jul 2026 · Select a Manager and/or Centre below to filter every table and chart on this sheet
A5: Second Level Manager: | B5: All Managers | D5: Centre: | E5: All Centres
A6: The Centre list narrows to the selected Manager's centres — if you switch Manager, reopen the Centre dropdown and pick again.
A7: internal: | B7: =IF($B$5="All Managers","*",$B$5) | C7: =IF($E$5="All Centres","*",$E$5)
A9: Visits in View | C9: Overall % Need Improvement | E9: Weakest Section | G9: Top Gap Item
A10: =COUNTIFS(Visits!$A$2:$A$75,$B$7,Visits!$B$2:$B$75,$C$7) | C10: =IFERROR((SUMIFS(Visits!$F$2:$F$75,Visits!$A$2:$A$75,$B$7,Visits!$B$2:$B$75,$C$7)+SUMIFS(Visits!$I$2:$I$75,Visits!$A$2:$A$75,$B$7,Visits!$B$2:$B$75,$C$7)+SUMIFS(Visits!$L$2:$L$75,Visits!$A$2:$A$75,$B$7,Visits!$B$2:$B$75,$C$7)+SUMIFS(Visits!$O$2:$O$75,Visits!$A$2:$A$75,$B$7,Visits!$B$2:$B$75,$C$7))/((SUMIFS(Visits!$E$2:$E$75,Visits!$A$2:$A$75,$B$7,Visits!$B$2:$B$75,$C$7)+SUMIFS(Visits!$F$2:$F$75,Visits!$A$2:$A$75,$B$7,Visits!$B$2:$B$75,$C$7))+(SUMIFS(Visits!$H$2:$H$75,Visits!$A$2:$A$75,$B$7,Visits!$B$2:$B$75,$C$7)+SUMIFS(Visits!$I$2:$I$75,Visits!$A$2:$A$75,$B$7,Visits!$B$2:$B$75,$C$7))+(SUMIFS(Visits!$K$2:$K$75,Visits!$A$2:$A$75,$B$7,Visits!$B$2:$B$75,$C$7)+SUMIFS(Visits!$L$2:$L$75,Visits!$A$2:$A$75,$B$7,Visits!$B$2:$B$75,$C$7))+(SUMIFS(Visits!$N$2:$N$75,Visits!$A$2:$A$75,$B$7,Visits!$B$2:$B$75,$C$7)+SUMIFS(Visits!$O$2:$O$75,Visits!$A$2:$A$75,$B$7,Visits!$B$2:$B$75,$C$7))),0) | E10: =INDEX($A$18:$A$21,MATCH(MAX($E$18:$E$21),$E$18:$E$21,0)) | G10: =B26
A12: visits matching current filter | C12: ="Of "&SUM($B$18:$D$21)&" checklist items: "&SUM($C$18:$C$21)&" Need Improvement, "&SUM($D$18:$D$21)&" Not Applicable." | E12: ="Of "&(INDEX($B$18:$B$21,MATCH(MAX($E$18:$E$21),$E$18:$E$21,0))+INDEX($C$18:$C$21,MATCH(MAX($E$18:$E$21),$E$18:$E$21,0))+INDEX($D$18:$D$21,MATCH(MAX($E$18:$E$21),$E$18:$E$21,0)))&" items in this section: "&INDEX($C$18:$C$21,MATCH(MAX($E$18:$E$21),$E$18:$E$21,0))&" Need Improvement, "&INDEX($D$18:$D$21,MATCH(MAX($E$18:$E$21),$E$18:$E$21,0))&" Not Applicable ("&TEXT(MAX($E$18:$E$21),"0.0%")&")." | G12: most-flagged single checklist item in view
A16: Section-Wise Compliance
A17: Section | B17: All is Well | C17: Need Improvement | D17: Not Applicable | E17: % Need Improvement
A18: Data Check | B18: =SUMIFS(Visits!$E$2:$E$75,Visits!$A$2:$A$75,$B$7,Visits!$B$2:$B$75,$C$7) | C18: =SUMIFS(Visits!$F$2:$F$75,Visits!$A$2:$A$75,$B$7,Visits!$B$2:$B$75,$C$7) | D18: =SUMIFS(Visits!$G$2:$G$75,Visits!$A$2:$A$75,$B$7,Visits!$B$2:$B$75,$C$7) | E18: =IFERROR(C18/(B18+C18),0)
A19: Infra Check | B19: =SUMIFS(Visits!$H$2:$H$75,Visits!$A$2:$A$75,$B$7,Visits!$B$2:$B$75,$C$7) | C19: =SUMIFS(Visits!$I$2:$I$75,Visits!$A$2:$A$75,$B$7,Visits!$B$2:$B$75,$C$7) | D19: =SUMIFS(Visits!$J$2:$J$75,Visits!$A$2:$A$75,$B$7,Visits!$B$2:$B$75,$C$7) | E19: =IFERROR(C19/(B19+C19),0)
A20: Process Check | B20: =SUMIFS(Visits!$K$2:$K$75,Visits!$A$2:$A$75,$B$7,Visits!$B$2:$B$75,$C$7) | C20: =SUMIFS(Visits!$L$2:$L$75,Visits!$A$2:$A$75,$B$7,Visits!$B$2:$B$75,$C$7) | D20: =SUMIFS(Visits!$M$2:$M$75,Visits!$A$2:$A$75,$B$7,Visits!$B$2:$B$75,$C$7) | E20: =IFERROR(C20/(B20+C20),0)
A21: Aspirant Interaction | B21: =SUMIFS(Visits!$N$2:$N$75,Visits!$A$2:$A$75,$B$7,Visits!$B$2:$B$75,$C$7) | C21: =SUMIFS(Visits!$O$2:$O$75,Visits!$A$2:$A$75,$B$7,Visits!$B$2:$B$75,$C$7) | D21: =SUMIFS(Visits!$P$2:$P$75,Visits!$A$2:$A$75,$B$7,Visits!$B$2:$B$75,$C$7) | E21: =IFERROR(C21/(B21+C21),0)
A23: Need Improvement Spotlight — Top 15 Checklist Items
A24: Ranked by number of “Need Improvement” flags among visits currently in view
A25: Section | B25: Checklist Item | C25: Need Improvement | D25: Applicable N | E25: % Need Improvement
A26: =IFERROR(INDEX(ItemStats!$A$2:$A$50,MATCH(LARGE(ItemStats!$G$2:$G$50,1),ItemStats!$G$2:$G$50,0)),"") | B26: =IFERROR(INDEX(ItemStats!$B$2:$B$50,MATCH(LARGE(ItemStats!$G$2:$G$50,1),ItemStats!$G$2:$G$50,0)),"") | C26: =IFERROR(INDEX(ItemStats!$C$2:$C$50,MATCH(LARGE(ItemStats!$G$2:$G$50,1),ItemStats!$G$2:$G$50,0)),"") | D26: =IFERROR(INDEX(ItemStats!$E$2:$E$50,MATCH(LARGE(ItemStats!$G$2:$G$50,1),ItemStats!$G$2:$G$50,0)),"") | E26: =IFERROR(INDEX(ItemStats!$F$2:$F$50,MATCH(LARGE(ItemStats!$G$2:$G$50,1),ItemStats!$G$2:$G$50,0)),"")
A27: =IFERROR(INDEX(ItemStats!$A$2:$A$50,MATCH(LARGE(ItemStats!$G$2:$G$50,2),ItemStats!$G$2:$G$50,0)),"") | B27: =IFERROR(INDEX(ItemStats!$B$2:$B$50,MATCH(LARGE(ItemStats!$G$2:$G$50,2),ItemStats!$G$2:$G$50,0)),"") | C27: =IFERROR(INDEX(ItemStats!$C$2:$C$50,MATCH(LARGE(ItemStats!$G$2:$G$50,2),ItemStats!$G$2:$G$50,0)),"") | D27: =IFERROR(INDEX(ItemStats!$E$2:$E$50,MATCH(LARGE(ItemStats!$G$2:$G$50,2),ItemStats!$G$2:$G$50,0)),"") | E27: =IFERROR(INDEX(ItemStats!$F$2:$F$50,MATCH(LARGE(ItemStats!$G$2:$G$50,2),ItemStats!$G$2:$G$50,0)),"")
A28: =IFERROR(INDEX(ItemStats!$A$2:$A$50,MATCH(LARGE(ItemStats!$G$2:$G$50,3),ItemStats!$G$2:$G$50,0)),"") | B28: =IFERROR(INDEX(ItemStats!$B$2:$B$50,MATCH(LARGE(ItemStats!$G$2:$G$50,3),ItemStats!$G$2:$G$50,0)),"") | C28: =IFERROR(INDEX(ItemStats!$C$2:$C$50,MATCH(LARGE(ItemStats!$G$2:$G$50,3),ItemStats!$G$2:$G$50,0)),"") | D28: =IFERROR(INDEX(ItemStats!$E$2:$E$50,MATCH(LARGE(ItemStats!$G$2:$G$50,3),ItemStats!$G$2:$G$50,0)),"") | E28: =IFERROR(INDEX(ItemStats!$F$2:$F$50,MATCH(LARGE(ItemStats!$G$2:$G$50,3),ItemStats!$G$2:$G$50,0)),"")
A29: =IFERROR(INDEX(ItemStats!$A$2:$A$50,MATCH(LARGE(ItemStats!$G$2:$G$50,4),ItemStats!$G$2:$G$50,0)),"") | B29: =IFERROR(INDEX(ItemStats!$B$2:$B$50,MATCH(LARGE(ItemStats!$G$2:$G$50,4),ItemStats!$G$2:$G$50,0)),"") | C29: =IFERROR(INDEX(ItemStats!$C$2:$C$50,MATCH(LARGE(ItemStats!$G$2:$G$50,4),ItemStats!$G$2:$G$50,0)),"") | D29: =IFERROR(INDEX(ItemStats!$E$2:$E$50,MATCH(LARGE(ItemStats!$G$2:$G$50,4),ItemStats!$G$2:$G$50,0)),"") | E29: =IFERROR(INDEX(ItemStats!$F$2:$F$50,MATCH(LARGE(ItemStats!$G$2:$G$50,4),ItemStats!$G$2:$G$50,0)),"")
A30: =IFERROR(INDEX(ItemStats!$A$2:$A$50,MATCH(LARGE(ItemStats!$G$2:$G$50,5),ItemStats!$G$2:$G$50,0)),"") | B30: =IFERROR(INDEX(ItemStats!$B$2:$B$50,MATCH(LARGE(ItemStats!$G$2:$G$50,5),ItemStats!$G$2:$G$50,0)),"") | C30: =IFERROR(INDEX(ItemStats!$C$2:$C$50,MATCH(LARGE(ItemStats!$G$2:$G$50,5),ItemStats!$G$2:$G$50,0)),"") | D30: =IFERROR(INDEX(ItemStats!$E$2:$E$50,MATCH(LARGE(ItemStats!$G$2:$G$50,5),ItemStats!$G$2:$G$50,0)),"") | E30: =IFERROR(INDEX(ItemStats!$F$2:$F$50,MATCH(LARGE(ItemStats!$G$2:$G$50,5),ItemStats!$G$2:$G$50,0)),"")
A31: =IFERROR(INDEX(ItemStats!$A$2:$A$50,MATCH(LARGE(ItemStats!$G$2:$G$50,6),ItemStats!$G$2:$G$50,0)),"") | B31: =IFERROR(INDEX(ItemStats!$B$2:$B$50,MATCH(LARGE(ItemStats!$G$2:$G$50,6),ItemStats!$G$2:$G$50,0)),"") | C31: =IFERROR(INDEX(ItemStats!$C$2:$C$50,MATCH(LARGE(ItemStats!$G$2:$G$50,6),ItemStats!$G$2:$G$50,0)),"") | D31: =IFERROR(INDEX(ItemStats!$E$2:$E$50,MATCH(LARGE(ItemStats!$G$2:$G$50,6),ItemStats!$G$2:$G$50,0)),"") | E31: =IFERROR(INDEX(ItemStats!$F$2:$F$50,MATCH(LARGE(ItemStats!$G$2:$G$50,6),ItemStats!$G$2:$G$50,0)),"")
A32: =IFERROR(INDEX(ItemStats!$A$2:$A$50,MATCH(LARGE(ItemStats!$G$2:$G$50,7),ItemStats!$G$2:$G$50,0)),"") | B32: =IFERROR(INDEX(ItemStats!$B$2:$B$50,MATCH(LARGE(ItemStats!$G$2:$G$50,7),ItemStats!$G$2:$G$50,0)),"") | C32: =IFERROR(INDEX(ItemStats!$C$2:$C$50,MATCH(LARGE(ItemStats!$G$2:$G$50,7),ItemStats!$G$2:$G$50,0)),"") | D32: =IFERROR(INDEX(ItemStats!$E$2:$E$50,MATCH(LARGE(ItemStats!$G$2:$G$50,7),ItemStats!$G$2:$G$50,0)),"") | E32: =IFERROR(INDEX(ItemStats!$F$2:$F$50,MATCH(LARGE(ItemStats!$G$2:$G$50,7),ItemStats!$G$2:$G$50,0)),"")
A33: =IFERROR(INDEX(ItemStats!$A$2:$A$50,MATCH(LARGE(ItemStats!$G$2:$G$50,8),ItemStats!$G$2:$G$50,0)),"") | B33: =IFERROR(INDEX(ItemStats!$B$2:$B$50,MATCH(LARGE(ItemStats!$G$2:$G$50,8),ItemStats!$G$2:$G$50,0)),"") | C33: =IFERROR(INDEX(ItemStats!$C$2:$C$50,MATCH(LARGE(ItemStats!$G$2:$G$50,8),ItemStats!$G$2:$G$50,0)),"") | D33: =IFERROR(INDEX(ItemStats!$E$2:$E$50,MATCH(LARGE(ItemStats!$G$2:$G$50,8),ItemStats!$G$2:$G$50,0)),"") | E33: =IFERROR(INDEX(ItemStats!$F$2:$F$50,MATCH(LARGE(ItemStats!$G$2:$G$50,8),ItemStats!$G$2:$G$50,0)),"")
A34: =IFERROR(INDEX(ItemStats!$A$2:$A$50,MATCH(LARGE(ItemStats!$G$2:$G$50,9),ItemStats!$G$2:$G$50,0)),"") | B34: =IFERROR(INDEX(ItemStats!$B$2:$B$50,MATCH(LARGE(ItemStats!$G$2:$G$50,9),ItemStats!$G$2:$G$50,0)),"") | C34: =IFERROR(INDEX(ItemStats!$C$2:$C$50,MATCH(LARGE(ItemStats!$G$2:$G$50,9),ItemStats!$G$2:$G$50,0)),"") | D34: =IFERROR(INDEX(ItemStats!$E$2:$E$50,MATCH(LARGE(ItemStats!$G$2:$G$50,9),ItemStats!$G$2:$G$50,0)),"") | E34: =IFERROR(INDEX(ItemStats!$F$2:$F$50,MATCH(LARGE(ItemStats!$G$2:$G$50,9),ItemStats!$G$2:$G$50,0)),"")
A35: =IFERROR(INDEX(ItemStats!$A$2:$A$50,MATCH(LARGE(ItemStats!$G$2:$G$50,10),ItemStats!$G$2:$G$50,0)),"") | B35: =IFERROR(INDEX(ItemStats!$B$2:$B$50,MATCH(LARGE(ItemStats!$G$2:$G$50,10),ItemStats!$G$2:$G$50,0)),"") | C35: =IFERROR(INDEX(ItemStats!$C$2:$C$50,MATCH(LARGE(ItemStats!$G$2:$G$50,10),ItemStats!$G$2:$G$50,0)),"") | D35: =IFERROR(INDEX(ItemStats!$E$2:$E$50,MATCH(LARGE(ItemStats!$G$2:$G$50,10),ItemStats!$G$2:$G$50,0)),"") | E35: =IFERROR(INDEX(ItemStats!$F$2:$F$50,MATCH(LARGE(ItemStats!$G$2:$G$50,10),ItemStats!$G$2:$G$50,0)),"")
A36: =IFERROR(INDEX(ItemStats!$A$2:$A$50,MATCH(LARGE(ItemStats!$G$2:$G$50,11),ItemStats!$G$2:$G$50,0)),"") | B36: =IFERROR(INDEX(ItemStats!$B$2:$B$50,MATCH(LARGE(ItemStats!$G$2:$G$50,11),ItemStats!$G$2:$G$50,0)),"") | C36: =IFERROR(INDEX(ItemStats!$C$2:$C$50,MATCH(LARGE(ItemStats!$G$2:$G$50,11),ItemStats!$G$2:$G$50,0)),"") | D36: =IFERROR(INDEX(ItemStats!$E$2:$E$50,MATCH(LARGE(ItemStats!$G$2:$G$50,11),ItemStats!$G$2:$G$50,0)),"") | E36: =IFERROR(INDEX(ItemStats!$F$2:$F$50,MATCH(LARGE(ItemStats!$G$2:$G$50,11),ItemStats!$G$2:$G$50,0)),"")
A37: =IFERROR(INDEX(ItemStats!$A$2:$A$50,MATCH(LARGE(ItemStats!$G$2:$G$50,12),ItemStats!$G$2:$G$50,0)),"") | B37: =IFERROR(INDEX(ItemStats!$B$2:$B$50,MATCH(LARGE(ItemStats!$G$2:$G$50,12),ItemStats!$G$2:$G$50,0)),"") | C37: =IFERROR(INDEX(ItemStats!$C$2:$C$50,MATCH(LARGE(ItemStats!$G$2:$G$50,12),ItemStats!$G$2:$G$50,0)),"") | D37: =IFERROR(INDEX(ItemStats!$E$2:$E$50,MATCH(LARGE(ItemStats!$G$2:$G$50,12),ItemStats!$G$2:$G$50,0)),"") | E37: =IFERROR(INDEX(ItemStats!$F$2:$F$50,MATCH(LARGE(ItemStats!$G$2:$G$50,12),ItemStats!$G$2:$G$50,0)),"")
A38: =IFERROR(INDEX(ItemStats!$A$2:$A$50,MATCH(LARGE(ItemStats!$G$2:$G$50,13),ItemStats!$G$2:$G$50,0)),"") | B38: =IFERROR(INDEX(ItemStats!$B$2:$B$50,MATCH(LARGE(ItemStats!$G$2:$G$50,13),ItemStats!$G$2:$G$50,0)),"") | C38: =IFERROR(INDEX(ItemStats!$C$2:$C$50,MATCH(LARGE(ItemStats!$G$2:$G$50,13),ItemStats!$G$2:$G$50,0)),"") | D38: =IFERROR(INDEX(ItemStats!$E$2:$E$50,MATCH(LARGE(ItemStats!$G$2:$G$50,13),ItemStats!$G$2:$G$50,0)),"") | E38: =IFERROR(INDEX(ItemStats!$F$2:$F$50,MATCH(LARGE(ItemStats!$G$2:$G$50,13),ItemStats!$G$2:$G$50,0)),"")
A39: =IFERROR(INDEX(ItemStats!$A$2:$A$50,MATCH(LARGE(ItemStats!$G$2:$G$50,14),ItemStats!$G$2:$G$50,0)),"") | B39: =IFERROR(INDEX(ItemStats!$B$2:$B$50,MATCH(LARGE(ItemStats!$G$2:$G$50,14),ItemStats!$G$2:$G$50,0)),"") | C39: =IFERROR(INDEX(ItemStats!$C$2:$C$50,MATCH(LARGE(ItemStats!$G$2:$G$50,14),ItemStats!$G$2:$G$50,0)),"") | D39: =IFERROR(INDEX(ItemStats!$E$2:$E$50,MATCH(LARGE(ItemStats!$G$2:$G$50,14),ItemStats!$G$2:$G$50,0)),"") | E39: =IFERROR(INDEX(ItemStats!$F$2:$F$50,MATCH(LARGE(ItemStats!$G$2:$G$50,14),ItemStats!$G$2:$G$50,0)),"")
A40: =IFERROR(INDEX(ItemStats!$A$2:$A$50,MATCH(LARGE(ItemStats!$G$2:$G$50,15),ItemStats!$G$2:$G$50,0)),"") | B40: =IFERROR(INDEX(ItemStats!$B$2:$B$50,MATCH(LARGE(ItemStats!$G$2:$G$50,15),ItemStats!$G$2:$G$50,0)),"") | C40: =IFERROR(INDEX(ItemStats!$C$2:$C$50,MATCH(LARGE(ItemStats!$G$2:$G$50,15),ItemStats!$G$2:$G$50,0)),"") | D40: =IFERROR(INDEX(ItemStats!$E$2:$E$50,MATCH(LARGE(ItemStats!$G$2:$G$50,15),ItemStats!$G$2:$G$50,0)),"") | E40: =IFERROR(INDEX(ItemStats!$F$2:$F$50,MATCH(LARGE(ItemStats!$G$2:$G$50,15),ItemStats!$G$2:$G$50,0)),"")

Sheet Reflections
A1: Field Reflections — filtered by Dashboard selection
A3: This list updates automatically based on the Manager / Centre selected on the Dashboard sheet.
A5: Centre | B5: Manager | C5: Program | D5: Date | E5: Key bottleneck resolved | F5: Placement % action | G5: Batch on-time action
A6: =IFERROR(INDEX(Visits!$B$2:$B$75,MATCH(1,Visits!$U$2:$U$75,0)),"") | B6: =IFERROR(INDEX(Visits!$A$2:$A$75,MATCH(1,Visits!$U$2:$U$75,0)),"") | C6: =IFERROR(INDEX(Visits!$C$2:$C$75,MATCH(1,Visits!$U$2:$U$75,0)),"") | D6: =IFERROR(INDEX(Visits!$D$2:$D$75,MATCH(1,Visits!$U$2:$U$75,0)),"") | E6: =IFERROR(INDEX(Visits!$Q$2:$Q$75,MATCH(1,Visits!$U$2:$U$75,0)),"") | F6: =IFERROR(INDEX(Visits!$R$2:$R$75,MATCH(1,Visits!$U$2:$U$75,0)),"") | G6: =IFERROR(INDEX(Visits!$S$2:$S$75,MATCH(1,Visits!$U$2:$U$75,0)),"")
A7: =IFERROR(INDEX(Visits!$B$2:$B$75,MATCH(2,Visits!$U$2:$U$75,0)),"") | B7: =IFERROR(INDEX(Visits!$A$2:$A$75,MATCH(2,Visits!$U$2:$U$75,0)),"") | C7: =IFERROR(INDEX(Visits!$C$2:$C$75,MATCH(2,Visits!$U$2:$U$75,0)),"") | D7: =IFERROR(INDEX(Visits!$D$2:$D$75,MATCH(2,Visits!$U$2:$U$75,0)),"") | E7: =IFERROR(INDEX(Visits!$Q$2:$Q$75,MATCH(2,Visits!$U$2:$U$75,0)),"") | F7: =IFERROR(INDEX(Visits!$R$2:$R$75,MATCH(2,Visits!$U$2:$U$75,0)),"") | G7: =IFERROR(INDEX(Visits!$S$2:$S$75,MATCH(2,Visits!$U$2:$U$75,0)),"")
A8: =IFERROR(INDEX(Visits!$B$2:$B$75,MATCH(3,Visits!$U$2:$U$75,0)),"") | B8: =IFERROR(INDEX(Visits!$A$2:$A$75,MATCH(3,Visits!$U$2:$U$75,0)),"") | C8: =IFERROR(INDEX(Visits!$C$2:$C$75,MATCH(3,Visits!$U$2:$U$75,0)),"") | D8: =IFERROR(INDEX(Visits!$D$2:$D$75,MATCH(3,Visits!$U$2:$U$75,0)),"") | E8: =IFERROR(INDEX(Visits!$Q$2:$Q$75,MATCH(3,Visits!$U$2:$U$75,0)),"") | F8: =IFERROR(INDEX(Visits!$R$2:$R$75,MATCH(3,Visits!$U$2:$U$75,0)),"") | G8: =IFERROR(INDEX(Visits!$S$2:$S$75,MATCH(3,Visits!$U$2:$U$75,0)),"")
A9: =IFERROR(INDEX(Visits!$B$2:$B$75,MATCH(4,Visits!$U$2:$U$75,0)),"") | B9: =IFERROR(INDEX(Visits!$A$2:$A$75,MATCH(4,Visits!$U$2:$U$75,0)),"") | C9: =IFERROR(INDEX(Visits!$C$2:$C$75,MATCH(4,Visits!$U$2:$U$75,0)),"") | D9: =IFERROR(INDEX(Visits!$D$2:$D$75,MATCH(4,Visits!$U$2:$U$75,0)),"") | E9: =IFERROR(INDEX(Visits!$Q$2:$Q$75,MATCH(4,Visits!$U$2:$U$75,0)),"") | F9: =IFERROR(INDEX(Visits!$R$2:$R$75,MATCH(4,Visits!$U$2:$U$75,0)),"") | G9: =IFERROR(INDEX(Visits!$S$2:$S$75,MATCH(4,Visits!$U$2:$U$75,0)),"")
A10: =IFERROR(INDEX(Visits!$B$2:$B$75,MATCH(5,Visits!$U$2:$U$75,0)),"") | B10: =IFERROR(INDEX(Visits!$A$2:$A$75,MATCH(5,Visits!$U$2:$U$75,0)),"") | C10: =IFERROR(INDEX(Visits!$C$2:$C$75,MATCH(5,Visits!$U$2:$U$75,0)),"") | D10: =IFERROR(INDEX(Visits!$D$2:$D$75,MATCH(5,Visits!$U$2:$U$75,0)),"") | E10: =IFERROR(INDEX(Visits!$Q$2:$Q$75,MATCH(5,Visits!$U$2:$U$75,0)),"") | F10: =IFERROR(INDEX(Visits!$R$2:$R$75,MATCH(5,Visits!$U$2:$U$75,0)),"") | G10: =IFERROR(INDEX(Visits!$S$2:$S$75,MATCH(5,Visits!$U$2:$U$75,0)),"")
A11: =IFERROR(INDEX(Visits!$B$2:$B$75,MATCH(6,Visits!$U$2:$U$75,0)),"") | B11: =IFERROR(INDEX(Visits!$A$2:$A$75,MATCH(6,Visits!$U$2:$U$75,0)),"") | C11: =IFERROR(INDEX(Visits!$C$2:$C$75,MATCH(6,Visits!$U$2:$U$75,0)),"") | D11: =IFERROR(INDEX(Visits!$D$2:$D$75,MATCH(6,Visits!$U$2:$U$75,0)),"") | E11: =IFERROR(INDEX(Visits!$Q$2:$Q$75,MATCH(6,Visits!$U$2:$U$75,0)),"") | F11: =IFERROR(INDEX(Visits!$R$2:$R$75,MATCH(6,Visits!$U$2:$U$75,0)),"") | G11: =IFERROR(INDEX(Visits!$S$2:$S$75,MATCH(6,Visits!$U$2:$U$75,0)),"")
A12: =IFERROR(INDEX(Visits!$B$2:$B$75,MATCH(7,Visits!$U$2:$U$75,0)),"") | B12: =IFERROR(INDEX(Visits!$A$2:$A$75,MATCH(7,Visits!$U$2:$U$75,0)),"") | C12: =IFERROR(INDEX(Visits!$C$2:$C$75,MATCH(7,Visits!$U$2:$U$75,0)),"") | D12: =IFERROR(INDEX(Visits!$D$2:$D$75,MATCH(7,Visits!$U$2:$U$75,0)),"") | E12: =IFERROR(INDEX(Visits!$Q$2:$Q$75,MATCH(7,Visits!$U$2:$U$75,0)),"") | F12: =IFERROR(INDEX(Visits!$R$2:$R$75,MATCH(7,Visits!$U$2:$U$75,0)),"") | G12: =IFERROR(INDEX(Visits!$S$2:$S$75,MATCH(7,Visits!$U$2:$U$75,0)),"")
A13: =IFERROR(INDEX(Visits!$B$2:$B$75,MATCH(8,Visits!$U$2:$U$75,0)),"") | B13: =IFERROR(INDEX(Visits!$A$2:$A$75,MATCH(8,Visits!$U$2:$U$75,0)),"") | C13: =IFERROR(INDEX(Visits!$C$2:$C$75,MATCH(8,Visits!$U$2:$U$75,0)),"") | D13: =IFERROR(INDEX(Visits!$D$2:$D$75,MATCH(8,Visits!$U$2:$U$75,0)),"") | E13: =IFERROR(INDEX(Visits!$Q$2:$Q$75,MATCH(8,Visits!$U$2:$U$75,0)),"") | F13: =IFERROR(INDEX(Visits!$R$2:$R$75,MATCH(8,Visits!$U$2:$U$75,0)),"") | G13: =IFERROR(INDEX(Visits!$S$2:$S$75,MATCH(8,Visits!$U$2:$U$75,0)),"")
A14: =IFERROR(INDEX(Visits!$B$2:$B$75,MATCH(9,Visits!$U$2:$U$75,0)),"") | B14: =IFERROR(INDEX(Visits!$A$2:$A$75,MATCH(9,Visits!$U$2:$U$75,0)),"") | C14: =IFERROR(INDEX(Visits!$C$2:$C$75,MATCH(9,Visits!$U$2:$U$75,0)),"") | D14: =IFERROR(INDEX(Visits!$D$2:$D$75,MATCH(9,Visits!$U$2:$U$75,0)),"") | E14: =IFERROR(INDEX(Visits!$Q$2:$Q$75,MATCH(9,Visits!$U$2:$U$75,0)),"") | F14: =IFERROR(INDEX(Visits!$R$2:$R$75,MATCH(9,Visits!$U$2:$U$75,0)),"") | G14: =IFERROR(INDEX(Visits!$S$2:$S$75,MATCH(9,Visits!$U$2:$U$75,0)),"")
A15: =IFERROR(INDEX(Visits!$B$2:$B$75,MATCH(10,Visits!$U$2:$U$75,0)),"") | B15: =IFERROR(INDEX(Visits!$A$2:$A$75,MATCH(10,Visits!$U$2:$U$75,0)),"") | C15: =IFERROR(INDEX(Visits!$C$2:$C$75,MATCH(10,Visits!$U$2:$U$75,0)),"") | D15: =IFERROR(INDEX(Visits!$D$2:$D$75,MATCH(10,Visits!$U$2:$U$75,0)),"") | E15: =IFERROR(INDEX(Visits!$Q$2:$Q$75,MATCH(10,Visits!$U$2:$U$75,0)),"") | F15: =IFERROR(INDEX(Visits!$R$2:$R$75,MATCH(10,Visits!$U$2:$U$75,0)),"") | G15: =IFERROR(INDEX(Visits!$S$2:$S$75,MATCH(10,Visits!$U$2:$U$75,0)),"")
A16: =IFERROR(INDEX(Visits!$B$2:$B$75,MATCH(11,Visits!$U$2:$U$75,0)),"") | B16: =IFERROR(INDEX(Visits!$A$2:$A$75,MATCH(11,Visits!$U$2:$U$75,0)),"") | C16: =IFERROR(INDEX(Visits!$C$2:$C$75,MATCH(11,Visits!$U$2:$U$75,0)),"") | D16: =IFERROR(INDEX(Visits!$D$2:$D$75,MATCH(11,Visits!$U$2:$U$75,0)),"") | E16: =IFERROR(INDEX(Visits!$Q$2:$Q$75,MATCH(11,Visits!$U$2:$U$75,0)),"") | F16: =IFERROR(INDEX(Visits!$R$2:$R$75,MATCH(11,Visits!$U$2:$U$75,0)),"") | G16: =IFERROR(INDEX(Visits!$S$2:$S$75,MATCH(11,Visits!$U$2:$U$75,0)),"")
A17: =IFERROR(INDEX(Visits!$B$2:$B$75,MATCH(12,Visits!$U$2:$U$75,0)),"") | B17: =IFERROR(INDEX(Visits!$A$2:$A$75,MATCH(12,Visits!$U$2:$U$75,0)),"") | C17: =IFERROR(INDEX(Visits!$C$2:$C$75,MATCH(12,Visits!$U$2:$U$75,0)),"") | D17: =IFERROR(INDEX(Visits!$D$2:$D$75,MATCH(12,Visits!$U$2:$U$75,0)),"") | E17: =IFERROR(INDEX(Visits!$Q$2:$Q$75,MATCH(12,Visits!$U$2:$U$75,0)),"") | F17: =IFERROR(INDEX(Visits!$R$2:$R$75,MATCH(12,Visits!$U$2:$U$75,0)),"") | G17: =IFERROR(INDEX(Visits!$S$2:$S$75,MATCH(12,Visits!$U$2:$U$75,0)),"")
A18: =IFERROR(INDEX(Visits!$B$2:$B$75,MATCH(13,Visits!$U$2:$U$75,0)),"") | B18: =IFERROR(INDEX(Visits!$A$2:$A$75,MATCH(13,Visits!$U$2:$U$75,0)),"") | C18: =IFERROR(INDEX(Visits!$C$2:$C$75,MATCH(13,Visits!$U$2:$U$75,0)),"") | D18: =IFERROR(INDEX(Visits!$D$2:$D$75,MATCH(13,Visits!$U$2:$U$75,0)),"") | E18: =IFERROR(INDEX(Visits!$Q$2:$Q$75,MATCH(13,Visits!$U$2:$U$75,0)),"") | F18: =IFERROR(INDEX(Visits!$R$2:$R$75,MATCH(13,Visits!$U$2:$U$75,0)),"") | G18: =IFERROR(INDEX(Visits!$S$2:$S$75,MATCH(13,Visits!$U$2:$U$75,0)),"")
A19: =IFERROR(INDEX(Visits!$B$2:$B$75,MATCH(14,Visits!$U$2:$U$75,0)),"") | B19: =IFERROR(INDEX(Visits!$A$2:$A$75,MATCH(14,Visits!$U$2:$U$75,0)),"") | C19: =IFERROR(INDEX(Visits!$C$2:$C$75,MATCH(14,Visits!$U$2:$U$75,0)),"") | D19: =IFERROR(INDEX(Visits!$D$2:$D$75,MATCH(14,Visits!$U$2:$U$75,0)),"") | E19: =IFERROR(INDEX(Visits!$Q$2:$Q$75,MATCH(14,Visits!$U$2:$U$75,0)),"") | F19: =IFERROR(INDEX(Visits!$R$2:$R$75,MATCH(14,Visits!$U$2:$U$75,0)),"") | G19: =IFERROR(INDEX(Visits!$S$2:$S$75,MATCH(14,Visits!$U$2:$U$75,0)),"")
A20: =IFERROR(INDEX(Visits!$B$2:$B$75,MATCH(15,Visits!$U$2:$U$75,0)),"") | B20: =IFERROR(INDEX(Visits!$A$2:$A$75,MATCH(15,Visits!$U$2:$U$75,0)),"") | C20: =IFERROR(INDEX(Visits!$C$2:$C$75,MATCH(15,Visits!$U$2:$U$75,0)),"") | D20: =IFERROR(INDEX(Visits!$D$2:$D$75,MATCH(15,Visits!$U$2:$U$75,0)),"") | E20: =IFERROR(INDEX(Visits!$Q$2:$Q$75,MATCH(15,Visits!$U$2:$U$75,0)),"") | F20: =IFERROR(INDEX(Visits!$R$2:$R$75,MATCH(15,Visits!$U$2:$U$75,0)),"") | G20: =IFERROR(INDEX(Visits!$S$2:$S$75,MATCH(15,Visits!$U$2:$U$75,0)),"")
A21: =IFERROR(INDEX(Visits!$B$2:$B$75,MATCH(16,Visits!$U$2:$U$75,0)),"") | B21: =IFERROR(INDEX(Visits!$A$2:$A$75,MATCH(16,Visits!$U$2:$U$75,0)),"") | C21: =IFERROR(INDEX(Visits!$C$2:$C$75,MATCH(16,Visits!$U$2:$U$75,0)),"") | D21: =IFERROR(INDEX(Visits!$D$2:$D$75,MATCH(16,Visits!$U$2:$U$75,0)),"") | E21: =IFERROR(INDEX(Visits!$Q$2:$Q$75,MATCH(16,Visits!$U$2:$U$75,0)),"") | F21: =IFERROR(INDEX(Visits!$R$2:$R$75,MATCH(16,Visits!$U$2:$U$75,0)),"") | G21: =IFERROR(INDEX(Visits!$S$2:$S$75,MATCH(16,Visits!$U$2:$U$75,0)),"")
A22: =IFERROR(INDEX(Visits!$B$2:$B$75,MATCH(17,Visits!$U$2:$U$75,0)),"") | B22: =IFERROR(INDEX(Visits!$A$2:$A$75,MATCH(17,Visits!$U$2:$U$75,0)),"") | C22: =IFERROR(INDEX(Visits!$C$2:$C$75,MATCH(17,Visits!$U$2:$U$75,0)),"") | D22: =IFERROR(INDEX(Visits!$D$2:$D$75,MATCH(17,Visits!$U$2:$U$75,0)),"") | E22: =IFERROR(INDEX(Visits!$Q$2:$Q$75,MATCH(17,Visits!$U$2:$U$75,0)),"") | F22: =IFERROR(INDEX(Visits!$R$2:$R$75,MATCH(17,Visits!$U$2:$U$75,0)),"") | G22: =IFERROR(INDEX(Visits!$S$2:$S$75,MATCH(17,Visits!$U$2:$U$75,0)),"")
A23: =IFERROR(INDEX(Visits!$B$2:$B$75,MATCH(18,Visits!$U$2:$U$75,0)),"") | B23: =IFERROR(INDEX(Visits!$A$2:$A$75,MATCH(18,Visits!$U$2:$U$75,0)),"") | C23: =IFERROR(INDEX(Visits!$C$2:$C$75,MATCH(18,Visits!$U$2:$U$75,0)),"") | D23: =IFERROR(INDEX(Visits!$D$2:$D$75,MATCH(18,Visits!$U$2:$U$75,0)),"") | E23: =IFERROR(INDEX(Visits!$Q$2:$Q$75,MATCH(18,Visits!$U$2:$U$75,0)),"") | F23: =IFERROR(INDEX(Visits!$R$2:$R$75,MATCH(18,Visits!$U$2:$U$75,0)),"") | G23: =IFERROR(INDEX(Visits!$S$2:$S$75,MATCH(18,Visits!$U$2:$U$75,0)),"")
A24: =IFERROR(INDEX(Visits!$B$2:$B$75,MATCH(19,Visits!$U$2:$U$75,0)),"") | B24: =IFERROR(INDEX(Visits!$A$2:$A$75,MATCH(19,Visits!$U$2:$U$75,0)),"") | C24: =IFERROR(INDEX(Visits!$C$2:$C$75,MATCH(19,Visits!$U$2:$U$75,0)),"") | D24: =IFERROR(INDEX(Visits!$D$2:$D$75,MATCH(19,Visits!$U$2:$U$75,0)),"") | E24: =IFERROR(INDEX(Visits!$Q$2:$Q$75,MATCH(19,Visits!$U$2:$U$75,0)),"") | F24: =IFERROR(INDEX(Visits!$R$2:$R$75,MATCH(19,Visits!$U$2:$U$75,0)),"") | G24: =IFERROR(INDEX(Visits!$S$2:$S$75,MATCH(19,Visits!$U$2:$U$75,0)),"")
A25: =IFERROR(INDEX(Visits!$B$2:$B$75,MATCH(20,Visits!$U$2:$U$75,0)),"") | B25: =IFERROR(INDEX(Visits!$A$2:$A$75,MATCH(20,Visits!$U$2:$U$75,0)),"") | C25: =IFERROR(INDEX(Visits!$C$2:$C$75,MATCH(20,Visits!$U$2:$U$75,0)),"") | D25: =IFERROR(INDEX(Visits!$D$2:$D$75,MATCH(20,Visits!$U$2:$U$75,0)),"") | E25: =IFERROR(INDEX(Visits!$Q$2:$Q$75,MATCH(20,Visits!$U$2:$U$75,0)),"") | F25: =IFERROR(INDEX(Visits!$R$2:$R$75,MATCH(20,Visits!$U$2:$U$75,0)),"") | G25: =IFERROR(INDEX(Visits!$S$2:$S$75,MATCH(20,Visits!$U$2:$U$75,0)),"")
A26: =IFERROR(INDEX(Visits!$B$2:$B$75,MATCH(21,Visits!$U$2:$U$75,0)),"") | B26: =IFERROR(INDEX(Visits!$A$2:$A$75,MATCH(21,Visits!$U$2:$U$75,0)),"") | C26: =IFERROR(INDEX(Visits!$C$2:$C$75,MATCH(21,Visits!$U$2:$U$75,0)),"") | D26: =IFERROR(INDEX(Visits!$D$2:$D$75,MATCH(21,Visits!$U$2:$U$75,0)),"") | E26: =IFERROR(INDEX(Visits!$Q$2:$Q$75,MATCH(21,Visits!$U$2:$U$75,0)),"") | F26: =IFERROR(INDEX(Visits!$R$2:$R$75,MATCH(21,Visits!$U$2:$U$75,0)),"") | G26: =IFERROR(INDEX(Visits!$S$2:$S$75,MATCH(21,Visits!$U$2:$U$75,0)),"")
A27: =IFERROR(INDEX(Visits!$B$2:$B$75,MATCH(22,Visits!$U$2:$U$75,0)),"") | B27: =IFERROR(INDEX(Visits!$A$2:$A$75,MATCH(22,Visits!$U$2:$U$75,0)),"") | C27: =IFERROR(INDEX(Visits!$C$2:$C$75,MATCH(22,Visits!$U$2:$U$75,0)),"") | D27: =IFERROR(INDEX(Visits!$D$2:$D$75,MATCH(22,Visits!$U$2:$U$75,0)),"") | E27: =IFERROR(INDEX(Visits!$Q$2:$Q$75,MATCH(22,Visits!$U$2:$U$75,0)),"") | F27: =IFERROR(INDEX(Visits!$R$2:$R$75,MATCH(22,Visits!$U$2:$U$75,0)),"") | G27: =IFERROR(INDEX(Visits!$S$2:$S$75,MATCH(22,Visits!$U$2:$U$75,0)),"")
A28: =IFERROR(INDEX(Visits!$B$2:$B$75,MATCH(23,Visits!$U$2:$U$75,0)),"") | B28: =IFERROR(INDEX(Visits!$A$2:$A$75,MATCH(23,Visits!$U$2:$U$75,0)),"") | C28: =IFERROR(INDEX(Visits!$C$2:$C$75,MATCH(23,Visits!$U$2:$U$75,0)),"") | D28: =IFERROR(INDEX(Visits!$D$2:$D$75,MATCH(23,Visits!$U$2:$U$75,0)),"") | E28: =IFERROR(INDEX(Visits!$Q$2:$Q$75,MATCH(23,Visits!$U$2:$U$75,0)),"") | F28: =IFERROR(INDEX(Visits!$R$2:$R$75,MATCH(23,Visits!$U$2:$U$75,0)),"") | G28: =IFERROR(INDEX(Visits!$S$2:$S$75,MATCH(23,Visits!$U$2:$U$75,0)),"")
A29: =IFERROR(INDEX(Visits!$B$2:$B$75,MATCH(24,Visits!$U$2:$U$75,0)),"") | B29: =IFERROR(INDEX(Visits!$A$2:$A$75,MATCH(24,Visits!$U$2:$U$75,0)),"") | C29: =IFERROR(INDEX(Visits!$C$2:$C$75,MATCH(24,Visits!$U$2:$U$75,0)),"") | D29: =IFERROR(INDEX(Visits!$D$2:$D$75,MATCH(24,Visits!$U$2:$U$75,0)),"") | E29: =IFERROR(INDEX(Visits!$Q$2:$Q$75,MATCH(24,Visits!$U$2:$U$75,0)),"") | F29: =IFERROR(INDEX(Visits!$R$2:$R$75,MATCH(24,Visits!$U$2:$U$75,0)),"") | G29: =IFERROR(INDEX(Visits!$S$2:$S$75,MATCH(24,Visits!$U$2:$U$75,0)),"")
A30: =IFERROR(INDEX(Visits!$B$2:$B$75,MATCH(25,Visits!$U$2:$U$75,0)),"") | B30: =IFERROR(INDEX(Visits!$A$2:$A$75,MATCH(25,Visits!$U$2:$U$75,0)),"") | C30: =IFERROR(INDEX(Visits!$C$2:$C$75,MATCH(25,Visits!$U$2:$U$75,0)),"") | D30: =IFERROR(INDEX(Visits!$D$2:$D$75,MATCH(25,Visits!$U$2:$U$75,0)),"") | E30: =IFERROR(INDEX(Visits!$Q$2:$Q$75,MATCH(25,Visits!$U$2:$U$75,0)),"") | F30: =IFERROR(INDEX(Visits!$R$2:$R$75,MATCH(25,Visits!$U$2:$U$75,0)),"") | G30: =IFERROR(INDEX(Visits!$S$2:$S$75,MATCH(25,Visits!$U$2:$U$75,0)),"")
A31: =IFERROR(INDEX(Visits!$B$2:$B$75,MATCH(26,Visits!$U$2:$U$75,0)),"") | B31: =IFERROR(INDEX(Visits!$A$2:$A$75,MATCH(26,Visits!$U$2:$U$75,0)),"") | C31: =IFERROR(INDEX(Visits!$C$2:$C$75,MATCH(26,Visits!$U$2:$U$75,0)),"") | D31: =IFERROR(INDEX(Visits!$D$2:$D$75,MATCH(26,Visits!$U$2:$U$75,0)),"") | E31: =IFERROR(INDEX(Visits!$Q$2:$Q$75,MATCH(26,Visits!$U$2:$U$75,0)),"") | F31: =IFERROR(INDEX(Visits!$R$2:$R$75,MATCH(26,Visits!$U$2:$U$75,0)),"") | G31: =IFERROR(INDEX(Visits!$S$2:$S$75,MATCH(26,Visits!$U$2:$U$75,0)),"")
A32: =IFERROR(INDEX(Visits!$B$2:$B$75,MATCH(27,Visits!$U$2:$U$75,0)),"") | B32: =IFERROR(INDEX(Visits!$A$2:$A$75,MATCH(27,Visits!$U$2:$U$75,0)),"") | C32: =IFERROR(INDEX(Visits!$C$2:$C$75,MATCH(27,Visits!$U$2:$U$75,0)),"") | D32: =IFERROR(INDEX(Visits!$D$2:$D$75,MATCH(27,Visits!$U$2:$U$75,0)),"") | E32: =IFERROR(INDEX(Visits!$Q$2:$Q$75,MATCH(27,Visits!$U$2:$U$75,0)),"") | F32: =IFERROR(INDEX(Visits!$R$2:$R$75,MATCH(27,Visits!$U$2:$U$75,0)),"") | G32: =IFERROR(INDEX(Visits!$S$2:$S$75,MATCH(27,Visits!$U$2:$U$75,0)),"")
A33: =IFERROR(INDEX(Visits!$B$2:$B$75,MATCH(28,Visits!$U$2:$U$75,0)),"") | B33: =IFERROR(INDEX(Visits!$A$2:$A$75,MATCH(28,Visits!$U$2:$U$75,0)),"") | C33: =IFERROR(INDEX(Visits!$C$2:$C$75,MATCH(28,Visits!$U$2:$U$75,0)),"") | D33: =IFERROR(INDEX(Visits!$D$2:$D$75,MATCH(28,Visits!$U$2:$U$75,0)),"") | E33: =IFERROR(INDEX(Visits!$Q$2:$Q$75,MATCH(28,Visits!$U$2:$U$75,0)),"") | F33: =IFERROR(INDEX(Visits!$R$2:$R$75,MATCH(28,Visits!$U$2:$U$75,0)),"") | G33: =IFERROR(INDEX(Visits!$S$2:$S$75,MATCH(28,Visits!$U$2:$U$75,0)),"")
A34: =IFERROR(INDEX(Visits!$B$2:$B$75,MATCH(29,Visits!$U$2:$U$75,0)),"") | B34: =IFERROR(INDEX(Visits!$A$2:$A$75,MATCH(29,Visits!$U$2:$U$75,0)),"") | C34: =IFERROR(INDEX(Visits!$C$2:$C$75,MATCH(29,Visits!$U$2:$U$75,0)),"") | D34: =IFERROR(INDEX(Visits!$D$2:$D$75,MATCH(29,Visits!$U$2:$U$75,0)),"") | E34: =IFERROR(INDEX(Visits!$Q$2:$Q$75,MATCH(29,Visits!$U$2:$U$75,0)),"") | F34: =IFERROR(INDEX(Visits!$R$2:$R$75,MATCH(29,Visits!$U$2:$U$75,0)),"") | G34: =IFERROR(INDEX(Visits!$S$2:$S$75,MATCH(29,Visits!$U$2:$U$75,0)),"")
A35: =IFERROR(INDEX(Visits!$B$2:$B$75,MATCH(30,Visits!$U$2:$U$75,0)),"") | B35: =IFERROR(INDEX(Visits!$A$2:$A$75,MATCH(30,Visits!$U$2:$U$75,0)),"") | C35: =IFERROR(INDEX(Visits!$C$2:$C$75,MATCH(30,Visits!$U$2:$U$75,0)),"") | D35: =IFERROR(INDEX(Visits!$D$2:$D$75,MATCH(30,Visits!$U$2:$U$75,0)),"") | E35: =IFERROR(INDEX(Visits!$Q$2:$Q$75,MATCH(30,Visits!$U$2:$U$75,0)),"") | F35: =IFERROR(INDEX(Visits!$R$2:$R$75,MATCH(30,Visits!$U$2:$U$75,0)),"") | G35: =IFERROR(INDEX(Visits!$S$2:$S$75,MATCH(30,Visits!$U$2:$U$75,0)),"")
A36: =IFERROR(INDEX(Visits!$B$2:$B$75,MATCH(31,Visits!$U$2:$U$75,0)),"") | B36: =IFERROR(INDEX(Visits!$A$2:$A$75,MATCH(31,Visits!$U$2:$U$75,0)),"") | C36: =IFERROR(INDEX(Visits!$C$2:$C$75,MATCH(31,Visits!$U$2:$U$75,0)),"") | D36: =IFERROR(INDEX(Visits!$D$2:$D$75,MATCH(31,Visits!$U$2:$U$75,0)),"") | E36: =IFERROR(INDEX(Visits!$Q$2:$Q$75,MATCH(31,Visits!$U$2:$U$75,0)),"") | F36: =IFERROR(INDEX(Visits!$R$2:$R$75,MATCH(31,Visits!$U$2:$U$75,0)),"") | G36: =IFERROR(INDEX(Visits!$S$2:$S$75,MATCH(31,Visits!$U$2:$U$75,0)),"")
A37: =IFERROR(INDEX(Visits!$B$2:$B$75,MATCH(32,Visits!$U$2:$U$75,0)),"") | B37: =IFERROR(INDEX(Visits!$A$2:$A$75,MATCH(32,Visits!$U$2:$U$75,0)),"") | C37: =IFERROR(INDEX(Visits!$C$2:$C$75,MATCH(32,Visits!$U$2:$U$75,0)),"") | D37: =IFERROR(INDEX(Visits!$D$2:$D$75,MATCH(32,Visits!$U$2:$U$75,0)),"") | E37: =IFERROR(INDEX(Visits!$Q$2:$Q$75,MATCH(32,Visits!$U$2:$U$75,0)),"") | F37: =IFERROR(INDEX(Visits!$R$2:$R$75,MATCH(32,Visits!$U$2:$U$75,0)),"") | G37: =IFERROR(INDEX(Visits!$S$2:$S$75,MATCH(32,Visits!$U$2:$U$75,0)),"")
A38: =IFERROR(INDEX(Visits!$B$2:$B$75,MATCH(33,Visits!$U$2:$U$75,0)),"") | B38: =IFERROR(INDEX(Visits!$A$2:$A$75,MATCH(33,Visits!$U$2:$U$75,0)),"") | C38: =IFERROR(INDEX(Visits!$C$2:$C$75,MATCH(33,Visits!$U$2:$U$75,0)),"") | D38: =IFERROR(INDEX(Visits!$D$2:$D$75,MATCH(33,Visits!$U$2:$U$75,0)),"") | E38: =IFERROR(INDEX(Visits!$Q$2:$Q$75,MATCH(33,Visits!$U$2:$U$75,0)),"") | F38: =IFERROR(INDEX(Visits!$R$2:$R$75,MATCH(33,Visits!$U$2:$U$75,0)),"") | G38: =IFERROR(INDEX(Visits!$S$2:$S$75,MATCH(33,Visits!$U$2:$U$75,0)),"")
A39: =IFERROR(INDEX(Visits!$B$2:$B$75,MATCH(34,Visits!$U$2:$U$75,0)),"") | B39: =IFERROR(INDEX(Visits!$A$2:$A$75,MATCH(34,Visits!$U$2:$U$75,0)),"") | C39: =IFERROR(INDEX(Visits!$C$2:$C$75,MATCH(34,Visits!$U$2:$U$75,0)),"") | D39: =IFERROR(INDEX(Visits!$D$2:$D$75,MATCH(34,Visits!$U$2:$U$75,0)),"") | E39: =IFERROR(INDEX(Visits!$Q$2:$Q$75,MATCH(34,Visits!$U$2:$U$75,0)),"") | F39: =IFERROR(INDEX(Visits!$R$2:$R$75,MATCH(34,Visits!$U$2:$U$75,0)),"") | G39: =IFERROR(INDEX(Visits!$S$2:$S$75,MATCH(34,Visits!$U$2:$U$75,0)),"")
A40: =IFERROR(INDEX(Visits!$B$2:$B$75,MATCH(35,Visits!$U$2:$U$75,0)),"") | B40: =IFERROR(INDEX(Visits!$A$2:$A$75,MATCH(35,Visits!$U$2:$U$75,0)),"") | C40: =IFERROR(INDEX(Visits!$C$2:$C$75,MATCH(35,Visits!$U$2:$U$75,0)),"") | D40: =IFERROR(INDEX(Visits!$D$2:$D$75,MATCH(35,Visits!$U$2:$U$75,0)),"") | E40: =IFERROR(INDEX(Visits!$Q$2:$Q$75,MATCH(35,Visits!$U$2:$U$75,0)),"") | F40: =IFERROR(INDEX(Visits!$R$2:$R$75,MATCH(35,Visits!$U$2:$U$75,0)),"") | G40: =IFERROR(INDEX(Visits!$S$2:$S$75,MATCH(35,Visits!$U$2:$U$75,0)),"")
A41: =IFERROR(INDEX(Visits!$B$2:$B$75,MATCH(36,Visits!$U$2:$U$75,0)),"") | B41: =IFERROR(INDEX(Visits!$A$2:$A$75,MATCH(36,Visits!$U$2:$U$75,0)),"") | C41: =IFERROR(INDEX(Visits!$C$2:$C$75,MATCH(36,Visits!$U$2:$U$75,0)),"") | D41: =IFERROR(INDEX(Visits!$D$2:$D$75,MATCH(36,Visits!$U$2:$U$75,0)),"") | E41: =IFERROR(INDEX(Visits!$Q$2:$Q$75,MATCH(36,Visits!$U$2:$U$75,0)),"") | F41: =IFERROR(INDEX(Visits!$R$2:$R$75,MATCH(36,Visits!$U$2:$U$75,0)),"") | G41: =IFERROR(INDEX(Visits!$S$2:$S$75,MATCH(36,Visits!$U$2:$U$75,0)),"")
A42: =IFERROR(INDEX(Visits!$B$2:$B$75,MATCH(37,Visits!$U$2:$U$75,0)),"") | B42: =IFERROR(INDEX(Visits!$A$2:$A$75,MATCH(37,Visits!$U$2:$U$75,0)),"") | C42: =IFERROR(INDEX(Visits!$C$2:$C$75,MATCH(37,Visits!$U$2:$U$75,0)),"") | D42: =IFERROR(INDEX(Visits!$D$2:$D$75,MATCH(37,Visits!$U$2:$U$75,0)),"") | E42: =IFERROR(INDEX(Visits!$Q$2:$Q$75,MATCH(37,Visits!$U$2:$U$75,0)),"") | F42: =IFERROR(INDEX(Visits!$R$2:$R$75,MATCH(37,Visits!$U$2:$U$75,0)),"") | G42: =IFERROR(INDEX(Visits!$S$2:$S$75,MATCH(37,Visits!$U$2:$U$75,0)),"")
...

Sheet Visits
A1: Manager | B1: Centre | C1: Program | D1: Date | E1: DataCheck_AW | F1: DataCheck_NI | G1: DataCheck_NA | H1: InfraCheck_AW | I1: InfraCheck_NI | J1: InfraCheck_NA | K1: ProcessCheck_AW | L1: ProcessCheck_NI | M1: ProcessCheck_NA | N1: AspirantInt_AW | O1: AspirantInt_NI | P1: AspirantInt_NA | Q1: Q_Bottleneck | R1: Q_PlacementAction | S1: Q_BatchOnTimeAction | T1: MatchFlag | U1: MatchRank
A2: Phani | B2: Vijayanagaram | C2: Grow Youth | D2: 2026-07-02 | E2: 7 | F2: 0 | G2: 1 | H2: 4 | I2: 3 | J2: 1 | K2: 11 | L2: 4 | M2: 7 | N2: 10 | O2: 0 | P2: 1 | Q2: Sent old laptops to HO, and arranged repairing of counseling room chairs. | R2: I will share employer leads of Vizag | S2: I have provided SIP team support and 18 students enrolled in present batch | T2: =IF(AND(OR(Dashboard!$B$5="All Managers",A2=Dashboard!$B$5),OR(Dashboard!$E$5="All Centres",B2=Dashboard!$E$5)),1,0) | U2: =IF(T2=1,COUNTIF($T$2:T2,1),"")
A3: S Jakir | B3: Bommanahalli | C3: GROW Youth | D3: 2026-07-02 | E3: 6 | F3: 2 | G3: 0 | H3: 4 | I3: 2 | J3: 2 | K3: 14 | L3: 3 | M3: 5 | N3: 9 | O3: 0 | P3: 2 | Q3: Conducted a focused discussion with the new trainer, Mrs. Harshadha, to understand her experience in handling the first batch and the reasons for the lower skill shift outcomes. Also reviewed her approach to managing the current batch. Provided guidance on key processes to be followed, shared relevant insights and best practices, and encouraged her by appreciating her efforts and the good work she has been doing. | R3: Aspirant mapping with quality employers and exclusive job drives with reputed employers have been missing over the last three months. I need to reinforce these activities and ensure their consistent implementation going forward. | S3: Referrals need to improve . Need to discuss with Trainers and guide them | T3: =IF(AND(OR(Dashboard!$B$5="All Managers",A3=Dashboard!$B$5),OR(Dashboard!$E$5="All Centres",B3=Dashboard!$E$5)),1,0) | U3: =IF(T3=1,COUNTIF($T$2:T3,1),"")
A4: S Jakir | B4: Hoskote | C4: HQHCS | D4: 2026-07-03 | E4: 8 | F4: 0 | G4: 0 | H4: 6 | I4: 2 | J4: 0 | K4: 17 | L4: 2 | M4: 3 | N4: 10 | O4: 0 | P4: 1 | Q4: Visited the PG facility, had lunch, and held a discussion with the PG management team. They were instructed to ensure the provision of quality food and to maintain better cleanliness standards within the premises. | R4: Need to share employer new employer leads | S4: CA hiring has to close ( interview forms shared for approval ) & complete CA induction training soon after the onboarding . | T4: =IF(AND(OR(Dashboard!$B$5="All Managers",A4=Dashboard!$B$5),OR(Dashboard!$E$5="All Centres",B4=Dashboard!$E$5)),1,0) | U4: =IF(T4=1,COUNTIF($T$2:T4,1),"")
A5: Raghavender Rao | B5: Karimnagar | C5: Grow-Green-Solar | D5: 2026-07-01 | E5: 8 | F5: 0 | G5: 0 | H5: 5 | I5: 3 | J5: 0 | K5: 20 | L5: 0 | M5: 2 | N5: 11 | O5: 0 | P5: 0 | Q5: The early placement details are pending and require immediate approval. During the visit, I verified all aspirants through video calls and obtained approval from the COO. A total of 17 aspirants have been verified and approved. | R5: The center is following a well-structured placement plan after the training and assessment process. With my continuous support, the team has successfully placed aspirants in the solar industry, ensuring better employment opportunities and placement outcomes. | S5: I had already suggested that the target group should be ITI and Diploma colleges. The team is maintaining a proper database of eligible aspirants, which will help ensure timely mobilization and enable us to commence each batch as planned. | T5: =IF(AND(OR(Dashboard!$B$5="All Managers",A5=Dashboard!$B$5),OR(Dashboard!$E$5="All Centres",B5=Dashboard!$E$5)),1,0) | U5: =IF(T5=1,COUNTIF($T$2:T5,1),"")
A6: Amit Chakraborty | B6: Barasat | C6: GROW Youth-JPM | D6: 2026-07-06 | E6: 6 | F6: 1 | G6: 1 | H6: 5 | I6: 2 | J6: 1 | K6: 12 | L6: 5 | M6: 5 | N6: 9 | O6: 0 | P6: 2 | Q6: During the visit, I identified and highlighted a few operational areas that were being overlooked in day-to-day activities. The discussion focused on establishing a more organized approach/tracker to monitor these activities through simple tracking regular reviews. Most operational processes at the center are functioning well | R6: All is Well | S6: Batch size is the struggle I reviewed the planned batch start date as of now and will keep tracking mobilization pipeline, counselling status and expected joining numbers every week so that I can identify risks at least 1 weeks before the batch start and create an action plan to ensure maintaining expected batch size | T6: =IF(AND(OR(Dashboard!$B$5="All Managers",A6=Dashboard!$B$5),OR(Dashboard!$E$5="All Centres",B6=Dashboard!$E$5)),1,0) | U6: =IF(T6=1,COUNTIF($T$2:T6,1),"")
A7: Bhargav Challa | B7: Warangal | C7: Grow Youth | D7: 2026-07-07 | E7: 5 | F7: 2 | G7: 1 | H7: 6 | I7: 1 | J7: 1 | K7: 6 | L7: 6 | M7: 10 | N7: 9 | O7: 0 | P7: 2 | R7: Connect the centre team with employers and arrange for interviews to make placemnets for batch 14 and remaining students from batch -13 | S7: Have identified and allocated a Tele Caller for next 10 days to do telecalling form the data generated through lokal app and other sources for thestart of Batch-16 at Warangal by 20th July | T7: =IF(AND(OR(Dashboard!$B$5="All Managers",A7=Dashboard!$B$5),OR(Dashboard!$E$5="All Centres",B7=Dashboard!$E$5)),1,0) | U7: =IF(T7=1,COUNTIF($T$2:T7,1),"")
A8: Raghavender Rao | B8: CFRSI-Chandanagar | C8: CFRSI-Innocation | D8: 2026-07-07 | E8: 7 | F8: 0 | G8: 1 | H8: 7 | I8: 0 | J8: 1 | K8: 12 | L8: 7 | M8: 3 | N8: 11 | O8: 0 | P8: 0 | Q8: we have prepared a structured outreach plan. Based on this plan, we are targeting the inception of the Pharma 3rd Batch. Additionally, the team will place greater emphasis on increasing the Digital batch inception count through focused outreach, mobilization, and candidate conversions to achieve the planned enrollment targets. | R8: Based on my network, I have shared potential employer leads, coordinated with institutions to conduct campus drives, and forwarded the employer details to the AH team for further follow-up and execution. | S8: Special focus was given to the Pharma batch. They required a database of Telangana college principals, including contact details of principals from private colleges. I have shared the required database with the team to support their outreach and mobilization efforts. | T8: =IF(AND(OR(Dashboard!$B$5="All Managers",A8=Dashboard!$B$5),OR(Dashboard!$E$5="All Centres",B8=Dashboard!$E$5)),1,0) | U8: =IF(T8=1,COUNTIF($T$2:T8,1),"")
A9: Amit Chakraborty | B9: Dumdum | C9: GROW Youth-CITI | D9: 2026-07-08 | E9: 6 | F9: 1 | G9: 1 | H9: 5 | I9: 2 | J9: 1 | K9: 11 | L9: 6 | M9: 5 | N9: 9 | O9: 0 | P9: 2 | Q9: Few process understanding Gap- Had a discussion with AH and Trainer giving them Clarity on Mock Interview Process and how it needs to be resolved and organized through following MDP guidelines. Requested AH to go through MDP course in Skilify | R9: All is well | S9: All is Well. | T9: =IF(AND(OR(Dashboard!$B$5="All Managers",A9=Dashboard!$B$5),OR(Dashboard!$E$5="All Centres",B9=Dashboard!$E$5)),1,0) | U9: =IF(T9=1,COUNTIF($T$2:T9,1),"")
A10: Mahaboob Basha | B10: Ambattur | C10: SCGBS-GROW-GREEN-EV | D10: 2026-07-10 | E10: 7 | F10: 1 | G10: 0 | H10: 7 | I10: 1 | J10: 0 | K10: 14 | L10: 4 | M10: 4 | N10: 9 | O10: 2 | P10: 0 | Q10: Prepare for audit (precheck) | R10: Employer connect | S10: Support on outreach | T10: =IF(AND(OR(Dashboard!$B$5="All Managers",A10=Dashboard!$B$5),OR(Dashboard!$E$5="All Centres",B10=Dashboard!$E$5)),1,0) | U10: =IF(T10=1,COUNTIF($T$2:T10,1),"")
A11: Amit Chakraborty | B11: Danapur | C11: GROW Youth-Accenture | D11: 2026-07-10 | E11: 4 | F11: 3 | G11: 1 | H11: 4 | I11: 3 | J11: 1 | K11: 9 | L11: 8 | M11: 5 | N11: 8 | O11: 1 | P11: 2 | Q11: My Centre visit this time was to identify process non-compliance and veracity issues. Based on the evidence gathered, the findings indicate a serious breach of data integrity was observed under the AH. The visit provided valuable insights into several underlying operational gaps that were not previously visible. These observations have enabled me to make more informed decisions to strengthen the center's operations, ensure alignment with organizational objectives, and implement corrective measures to minimize process deviations and compliance issues. | R11: With the resignation of the Trainer, there is a risk of delayed placement activities for Batch-80 and a potential impact on placement outcomes. Additionally, as AH also needs to be removed due to veracity issue, need to immediately align AH profiles for the Centre Conduct regular follow-ups with the team on the placement progress of Batch-80 and closely monitor daily placement activities. Align the AH-EC also with the center to facilitate timely placement opportunities a | S11: CA has been taking frequent leaves citing multiple reasons. Despite prior counseling and a formal warning regarding attendance and accountability, the pattern of unplanned leave has continued, impacting Centre operations, mobilization activities, and overall team stability. Action Point- Immediate support will be extended to source suitable CVs for a replacement CA to ensure continuity along. | T11: =IF(AND(OR(Dashboard!$B$5="All Managers",A11=Dashboard!$B$5),OR(Dashboard!$E$5="All Centres",B11=Dashboard!$E$5)),1,0) | U11: =IF(T11=1,COUNTIF($T$2:T11,1),"")
A12: Barna | B12: Daryaganj | C12: CITI Youth | D12: 2026-07-07 | E12: 5 | F12: 2 | G12: 1 | H12: 7 | I12: 0 | J12: 1 | K12: 10 | L12: 7 | M12: 5 | N12: 8 | O12: 0 | P12: 3 | Q12: Explain how to fill and maintain the Alumni Handholding & top 20 format and importance of the process. | R12: Provide Employer's leads initiate the batch placements for the current financial year. | S12: Share an outreach activities format where they can plan the weekly activity and number of leads and footfall generated from the activities. | T12: =IF(AND(OR(Dashboard!$B$5="All Managers",A12=Dashboard!$B$5),OR(Dashboard!$E$5="All Centres",B12=Dashboard!$E$5)),1,0) | U12: =IF(T12=1,COUNTIF($T$2:T12,1),"")
A13: Barna | B13: Shahdara | C13: Accenture (Youth) | D13: 2026-07-08 | E13: 5 | F13: 2 | G13: 1 | H13: 7 | I13: 0 | J13: 1 | K13: 9 | L13: 7 | M13: 6 | N13: 8 | O13: 0 | P13: 3 | Q13: Ensure that the Top 20 Employer List is maintained and regularly updated at the center. Team meetings should be formalized and documented either in the prescribed Team Meeting Format or through email. | R13: Ensuring that L&D mock interview must be maintained. | S13: Once again I explain the counselling check list and Pre ESA part. | T13: =IF(AND(OR(Dashboard!$B$5="All Managers",A13=Dashboard!$B$5),OR(Dashboard!$E$5="All Centres",B13=Dashboard!$E$5)),1,0) | U13: =IF(T13=1,COUNTIF($T$2:T13,1),"")
A14: Amit Chakraborty | B14: Kidwainagar | C14: Grow Youth-Accenture | D14: 2026-07-11 | E14: 3 | F14: 4 | G14: 1 | H14: 5 | I14: 2 | J14: 1 | K14: 10 | L14: 7 | M14: 5 | N14: 8 | O14: 1 | P14: 2 | Q14: As AH had resigned - Sourced few AH CV to immediately close the indent. Completed Day 10 report and removed non eligible candidate, including one underage aspirant where DOB was wrongly updated in Portal. Identified issues in System- 4 system not working and most need repairing of CPU power button | R14: I shall bre in touch with Batch 84 & 85, already spoken and met with some aspirants of the Batch to complete their Placement- Have shared them WFH opportunity at Startek and also, I shall talk to few more Employers to line up candidate. Weekly once I will connect to team on Placement improvement of the Batch till AH joins and support them with lead- I will also connect Rituparna our AH-EC to support them with local /good leads | S14: All is well till now Batches are starting on time | T14: =IF(AND(OR(Dashboard!$B$5="All Managers",A14=Dashboard!$B$5),OR(Dashboard!$E$5="All Centres",B14=Dashboard!$E$5)),1,0) | U14: =IF(T14=1,COUNTIF($T$2:T14,1),"")
A15: Bhargav Challa | B15: Gachibowli | C15: Grow Youth | D15: 2026-07-11 | E15: 4 | F15: 3 | G15: 1 | H15: 3 | I15: 4 | J15: 1 | K15: 4 | L15: 11 | M15: 7 | N15: 6 | O15: 3 | P15: 2 | Q15: Have oriented the team on following the mandatory centre processes of Mock Interview, Weekly Team Meeting, 25th day Aspirant report, maintaining hygeine of the centre. | S15: Guided the team on the importance of planning for mobilisation, focusing on referrals for upcoming batches, and effectively utilizing the AFR, Field Register, and CA Diary. Thsi would help in streamlining the outrech activities and help the batch start | T15: =IF(AND(OR(Dashboard!$B$5="All Managers",A15=Dashboard!$B$5),OR(Dashboard!$E$5="All Centres",B15=Dashboard!$E$5)),1,0) | U15: =IF(T15=1,COUNTIF($T$2:T15,1),"")
A16: Gagandeep Singh Sachar | B16: Vadodara Citi | C16: GROW youth | D16: 2026-07-01 | E16: 5 | F16: 2 | G16: 1 | H16: 5 | I16: 2 | J16: 1 | K16: 15 | L16: 1 | M16: 6 | N16: 9 | O16: 0 | P16: 2 | Q16: Trainer Resigned, Looked for 2-3 resume and done 1 interview | R16: Placement plan disscussed and also 2 employer connect shared | S16: New Tools planning done | T16: =IF(AND(OR(Dashboard!$B$5="All Managers",A16=Dashboard!$B$5),OR(Dashboard!$E$5="All Centres",B16=Dashboard!$E$5)),1,0) | U16: =IF(T16=1,COUNTIF($T$2:T16,1),"")
A17: Gagandeep Singh Sachar | B17: Vadodara HQHCS | C17: HQHCS | D17: 2026-07-02 | E17: 5 | F17: 3 | G17: 0 | H17: 6 | I17: 1 | J17: 1 | K17: 11 | L17: 6 | M17: 5 | N17: 8 | O17: 2 | P17: 1 | Q17: All Process orientation given and aligned with new project and planning | R17: Start seeing the quality of employers | S17: Review Mobilisation plan on weekly basis by deepak | T17: =IF(AND(OR(Dashboard!$B$5="All Managers",A17=Dashboard!$B$5),OR(Dashboard!$E$5="All Centres",B17=Dashboard!$E$5)),1,0) | U17: =IF(T17=1,COUNTIF($T$2:T17,1),"")
A18: Gagandeep Singh Sachar | B18: Vasai | C18: Grow youth | D18: 2026-07-13 | E18: 5 | F18: 2 | G18: 1 | H18: 7 | I18: 0 | J18: 1 | K18: 10 | L18: 5 | M18: 7 | N18: 8 | O18: 1 | P18: 2 | Q18: NA Case - 15 pending for Vasai - discuss with Sushma | R18: Placement to be completed in 15 days. | S18: its going well, New 1-2 mobilisation tools can be added | T18: =IF(AND(OR(Dashboard!$B$5="All Managers",A18=Dashboard!$B$5),OR(Dashboard!$E$5="All Centres",B18=Dashboard!$E$5)),1,0) | U18: =IF(T18=1,COUNTIF($T$2:T18,1),"")
A19: Barna | B19: Sarita Vihar | C19: Youth | D19: 2026-07-11 | E19: 6 | F19: 1 | G19: 1 | H19: 7 | I19: 0 | J19: 1 | K19: 12 | L19: 6 | M19: 4 | N19: 11 | O19: 0 | P19: 0 | Q19: Conducting video calls to clear the NA cases. | R19: Share employer leads with AH | S19: guided on the new outreach activities to be conducted and how to meassure footfalls and leads generated from the activities. | T19: =IF(AND(OR(Dashboard!$B$5="All Managers",A19=Dashboard!$B$5),OR(Dashboard!$E$5="All Centres",B19=Dashboard!$E$5)),1,0) | U19: =IF(T19=1,COUNTIF($T$2:T19,1),"")
A20: Barna | B20: NOIDA Sec 63 | C20: GROW Youth | D20: 2026-07-13 | E20: 3 | F20: 2 | G20: 3 | H20: 6 | I20: 1 | J20: 1 | K20: 6 | L20: 8 | M20: 8 | N20: 0 | O20: 0 | P20: 11 | Q20: Discuss with CA review the outreach efforts. | R20: Clarity given on the collection of Placement evidences. | S20: Reviewing the outreach activities. | T20: =IF(AND(OR(Dashboard!$B$5="All Managers",A20=Dashboard!$B$5),OR(Dashboard!$E$5="All Centres",B20=Dashboard!$E$5)),1,0) | U20: =IF(T20=1,COUNTIF($T$2:T20,1),"")
A21: Amit Chakraborty | B21: Alambagh | C21: GROW Youth-Accenture | D21: 2026-07-13 | E21: 4 | F21: 3 | G21: 1 | H21: 3 | I21: 3 | J21: 2 | K21: 15 | L21: 2 | M21: 5 | N21: 9 | O21: 0 | P21: 2 | Q21: 1 Trainer Resigned had interview 3 Profile and finalized 2 and shared CV with Trainer | R21: Present performance of FY 26-27 is good only need to keep on tracking FY 25-26 and support team with new Employers | S21: All is well. Present batch is delayed starting by 3-4 days and average B2 be around 7 days . Had a discussion with team on Planned batch start date which is delayed it shall start in next 3 days | T21: =IF(AND(OR(Dashboard!$B$5="All Managers",A21=Dashboard!$B$5),OR(Dashboard!$E$5="All Centres",B21=Dashboard!$E$5)),1,0) | U21: =IF(T21=1,COUNTIF($T$2:T21,1),"")
A22: Gagandeep Singh Sachar | B22: Thane | C22: Youth | D22: 2026-07-14 | E22: 5 | F22: 2 | G22: 1 | H22: 4 | I22: 2 | J22: 2 | K22: 10 | L22: 5 | M22: 7 | N22: 8 | O22: 1 | P22: 2 | Q22: AH interview for Belapur Done - Akshay | R22: NA case discussion | S22: No issue | T22: =IF(AND(OR(Dashboard!$B$5="All Managers",A22=Dashboard!$B$5),OR(Dashboard!$E$5="All Centres",B22=Dashboard!$E$5)),1,0) | U22: =IF(T22=1,COUNTIF($T$2:T22,1),"")
A23: Amit Chakraborty | B23: Lucknow-Indiranagar | C23: GROW Youth-CITI | D23: 2026-07-14 | E23: 6 | F23: 1 | G23: 1 | H23: 7 | I23: 0 | J23: 1 | K23: 17 | L23: 0 | M23: 5 | N23: 9 | O23: 0 | P23: 2 | Q23: Guided them on New QAE Pilot on Lucknow Indiranagar, gave them clarity on FCRA challenge they were facing | R23: All is Well- Benchmark Salary is a concern-Guided team on Planning well on Each Aspirants to ensure Placement is aligned | S23: All is well | T23: =IF(AND(OR(Dashboard!$B$5="All Managers",A23=Dashboard!$B$5),OR(Dashboard!$E$5="All Centres",B23=Dashboard!$E$5)),1,0) | U23: =IF(T23=1,COUNTIF($T$2:T23,1),"")
A24: Mahaboob Basha | B24: Velachery-Accenture Additional Grant | C24: GROW-Youth | D24: 2026-07-15 | E24: 7 | F24: 0 | G24: 1 | H24: 5 | I24: 1 | J24: 2 | K24: 15 | L24: 4 | M24: 3 | N24: 9 | O24: 2 | P24: 0 | Q24: Meeting with CA on performance | R24: Employer connect | S24: Data collection and outreach plan | T24: =IF(AND(OR(Dashboard!$B$5="All Managers",A24=Dashboard!$B$5),OR(Dashboard!$E$5="All Centres",B24=Dashboard!$E$5)),1,0) | U24: =IF(T24=1,COUNTIF($T$2:T24,1),"")
A25: Gagandeep Singh Sachar | B25: Swargate | C25: GROW | D25: 2026-07-15 | E25: 6 | F25: 1 | G25: 1 | H25: 7 | I25: 0 | J25: 1 | K25: 16 | L25: 0 | M25: 6 | N25: 10 | O25: 0 | P25: 1 | Q25: NA cases - Rejected due to BBM approval and Discuss with vendor on door repair | R25: Discuss aspirants 1-1 for all un placed | S25: Batch to start on time - We have discussed on the use of multiple tools | T25: =IF(AND(OR(Dashboard!$B$5="All Managers",A25=Dashboard!$B$5),OR(Dashboard!$E$5="All Centres",B25=Dashboard!$E$5)),1,0) | U25: =IF(T25=1,COUNTIF($T$2:T25,1),"")
A26: Sanjay Kumar Tarai | B26: Berhampur | C26: CITI | D26: 2026-07-14 | E26: 4 | F26: 3 | G26: 1 | H26: 5 | I26: 2 | J26: 1 | K26: 10 | L26: 8 | M26: 4 | N26: 8 | O26: 1 | P26: 2 | Q26: Weak process ownership and supervisory control at the centre level, leading to poor compliance, inconsistent training quality, delayed execution, and lack of accountability. New AH- Lack of managerial supervision by the Area Head (AH), still he needs handhold for couple of months till one complete batch cycle end. The centre currently lacks a disciplined Review, Feedback , Follow-up, Closure mechanism. I have clearly discussed with all team members and ensure all follows the agreed action points. Daily checklist review (HK, Trainer, CA). 15-minute morning planning meeting. End-of-day review of pending activities. Weekly classroom observation. Weekly documentation audit. Weekly placement and employer review. Weekly action tracker with target dates and closure status. | R26: As a second-level manager, I can improve placement percentage by institutionalizing a weekly placement management system that reviews the employer pipeline, candidate readiness. I can send weekly atlease one placement opportunity where Berhampur candidates can be placed. | S26: I engage myself in morning to discuss daily outreach planning, tools to be used for the day, areas with my suggestion wherever required to do it in better way and do review in daily evening for 10 min with CA and AH. | T26: =IF(AND(OR(Dashboard!$B$5="All Managers",A26=Dashboard!$B$5),OR(Dashboard!$E$5="All Centres",B26=Dashboard!$E$5)),1,0) | U26: =IF(T26=1,COUNTIF($T$2:T26,1),"")
A27: Bhargav Challa | B27: Bachupally | C27: Grow Youth | D27: 2026-07-15 | E27: 5 | F27: 2 | G27: 1 | H27: 6 | I27: 1 | J27: 1 | K27: 14 | L27: 2 | M27: 6 | N27: 7 | O27: 2 | P27: 2 | Q27: Oriented the centre on the need to follow the key process to be followed- Regularity and punctuality of the students, Transparent reporting of the data and their understanding of the programme | R27: Counseled the Batch-11 students to understand their career aspirations and preferred job roles. Developed a placement plan and interview line up's to ensure all students are placed within the next two weeks, in coordination with Sachin and the batch trainer. | T27: =IF(AND(OR(Dashboard!$B$5="All Managers",A27=Dashboard!$B$5),OR(Dashboard!$E$5="All Centres",B27=Dashboard!$E$5)),1,0) | U27: =IF(T27=1,COUNTIF($T$2:T27,1),"")
A28: Barna | B28: Nehru Nagar Durg | C28: Youth Accenture | D28: 2026-07-15 | E28: 4 | F28: 3 | G28: 1 | H28: 5 | I28: 2 | J28: 1 | K28: 8 | L28: 7 | M28: 7 | N28: 9 | O28: 0 | P28: 2 | Q28: Explained the assets Verification process | R28: Share Placement leads to conduct a campus drive at center. | S28: share a weekly outreach activity format Planned Vs Actuals. In that sheet defined 20+ outreach activities which needs to be carried out on weekly basis. Also Prepared a google form which capture basic information of the jobless candidates. It can be shared along with Whatsapp flyer. | T28: =IF(AND(OR(Dashboard!$B$5="All Managers",A28=Dashboard!$B$5),OR(Dashboard!$E$5="All Centres",B28=Dashboard!$E$5)),1,0) | U28: =IF(T28=1,COUNTIF($T$2:T28,1),"")
A29: Barna | B29: Gurgaon | C29: Youth (CITI) | D29: 2026-07-10 | E29: 7 | F29: 0 | G29: 1 | H29: 6 | I29: 1 | J29: 1 | K29: 10 | L29: 7 | M29: 5 | N29: 9 | O29: 0 | P29: 2 | Q29: NA cases discussed with AH. So that she can cleared it as soon as possible. | R29: Two employer leads shared with AH | S29: Weekly outreach sheet shared with the AH and CA. It will help them to planning the outreach activities | T29: =IF(AND(OR(Dashboard!$B$5="All Managers",A29=Dashboard!$B$5),OR(Dashboard!$E$5="All Centres",B29=Dashboard!$E$5)),1,0) | U29: =IF(T29=1,COUNTIF($T$2:T29,1),"")
A30: Barna | B30: Peeragarhi | C30: Youth CITI | D30: 2026-07-09 | E30: 5 | F30: 2 | G30: 1 | H30: 7 | I30: 0 | J30: 1 | K30: 9 | L30: 7 | M30: 6 | N30: 9 | O30: 0 | P30: 2 | Q30: Explain and aligned AH how placements and skill shift will takes place. | R30: Planning is done for the placements and discuss the dates for the batchwise placement closure reports to be shared. | S30: Explaining the Weekly outreach format and ensuring that it should be implemented as per the plan. | T30: =IF(AND(OR(Dashboard!$B$5="All Managers",A30=Dashboard!$B$5),OR(Dashboard!$E$5="All Centres",B30=Dashboard!$E$5)),1,0) | U30: =IF(T30=1,COUNTIF($T$2:T30,1),"")
A31: Gagandeep Singh Sachar | B31: Chinchwad - Pune | C31: Youth | D31: 2026-07-16 | E31: 6 | F31: 1 | G31: 1 | H31: 6 | I31: 1 | J31: 1 | K31: 10 | L31: 7 | M31: 5 | N31: 10 | O31: 0 | P31: 1 | Q31: Issue for light - Need to give a backup generator and Train will join from 20th July at center | R31: EC more need to be done. | S31: Data collection and Training to CA | T31: =IF(AND(OR(Dashboard!$B$5="All Managers",A31=Dashboard!$B$5),OR(Dashboard!$E$5="All Centres",B31=Dashboard!$E$5)),1,0) | U31: =IF(T31=1,COUNTIF($T$2:T31,1),"")
A32: Amit Chakraborty | B32: Bareilly | C32: GROW Youth- Accenture | D32: 2026-07-15 | E32: 6 | F32: 1 | G32: 1 | H32: 3 | I32: 4 | J32: 1 | K32: 13 | L32: 4 | M32: 5 | N32: 5 | O32: 4 | P32: 2 | Q32: 1)Identified process gap and trained team on Process 2) Qulaity Placement is a concern so guided team to share aspirant wise placement plan 3) Conducted session with Aspirants and cleared them on importance of Skillify courses and Refferal policy 4) AH session and Mock Interview found missing- Will track the same 5) In present batch it was found around 14 candidate are not regular and alligned-Attendance found poor- Removed all unserious candidate and discussed and guided team on Counselling process | R32: 1) Every week discussion and Plan on unplaced candidate shall be done with Bareilly Team 2) Will arrange a Personal counselling on relocation to Delhi/Noida will do | S32: Batch start is not a challenge huge dropout/removal has been a challenge - So I will personally monitor Day 1 report and if needed 1 to 1 interaction with Aspirant in next Batch | T32: =IF(AND(OR(Dashboard!$B$5="All Managers",A32=Dashboard!$B$5),OR(Dashboard!$E$5="All Centres",B32=Dashboard!$E$5)),1,0) | U32: =IF(T32=1,COUNTIF($T$2:T32,1),"")
A33: Barna | B33: Narmada Nagar Bilaspur | C33: Youth Accenture | D33: 2026-07-16 | E33: 7 | F33: 0 | G33: 1 | H33: 5 | I33: 2 | J33: 1 | K33: 9 | L33: 7 | M33: 6 | N33: 9 | O33: 0 | P33: 2 | Q33: Discussed on all the old NA cases | R33: Provided Leads for the placements | S33: Share and discussed the Weekly outreach sheet and ensure that all the mentioned activities must be implemented as per the plan. | T33: =IF(AND(OR(Dashboard!$B$5="All Managers",A33=Dashboard!$B$5),OR(Dashboard!$E$5="All Centres",B33=Dashboard!$E$5)),1,0) | U33: =IF(T33=1,COUNTIF($T$2:T33,1),"")
A34: Amit Chakraborty | B34: Baccha Park | C34: GROW Youth-Accenture | D34: 2026-07-16 | E34: 6 | F34: 0 | G34: 2 | H34: 4 | I34: 3 | J34: 1 | K34: 15 | L34: 2 | M34: 5 | N34: 9 | O34: 0 | P34: 2 | Q34: No major challenge observed in Centre. I conducted a session of Batch 88 on explaining Local and Out location opportunities in Meerut and around and benefit of joining Quality Organization | R34: Local placement opportunities continue to be a challenge in the region. To address this, I have already shared available job opportunities from Digitide and Tech Mahindra with the centre team. I will conduct an awareness and counselling session with the aspirants to help them understand the benefits of relocation, including better career prospects, higher employability, and long-term career growth. This will encourage greater willingness among aspirants to explore opportunities outside their local area | S34: All is well | T34: =IF(AND(OR(Dashboard!$B$5="All Managers",A34=Dashboard!$B$5),OR(Dashboard!$E$5="All Centres",B34=Dashboard!$E$5)),1,0) | U34: =IF(T34=1,COUNTIF($T$2:T34,1),"")
A35: Barna | B35: Lakhe Nagar Raipur | C35: Youth Accenture | D35: 2026-07-14 | E35: 5 | F35: 2 | G35: 1 | H35: 6 | I35: 1 | J35: 1 | K35: 9 | L35: 7 | M35: 6 | N35: 10 | O35: 0 | P35: 1 | Q35: Ensuring CA should collect the 10th Class marksheet for DOB. Team is collecting only last higher education proofs. | R35: Ensuring daily 8-10 interviews must be scheduled for both the programs. Also Shared employer connect lead | S35: The team is facing challenges in conducting online outreach. We discussed and planned the outreach strategy, and explained how they should carry forward the outreach activities to ensure timely batch starts. | T35: =IF(AND(OR(Dashboard!$B$5="All Managers",A35=Dashboard!$B$5),OR(Dashboard!$E$5="All Centres",B35=Dashboard!$E$5)),1,0) | U35: =IF(T35=1,COUNTIF($T$2:T35,1),"")
A36: Mahaboob Basha | B36: Coimbatore | C36: GROW-Youth-CITI | D36: 2026-07-17 | E36: 3 | F36: 4 | G36: 1 | H36: 7 | I36: 0 | J36: 1 | K36: 15 | L36: 1 | M36: 6 | N36: 10 | O36: 0 | P36: 1 | Q36: Met 2 employer at their place with AH, Found some gap in registration form, Check list and corrected | R36: Connect with the employer and set the aspirant mindset on day 1 | S36: Connect with community | T36: =IF(AND(OR(Dashboard!$B$5="All Managers",A36=Dashboard!$B$5),OR(Dashboard!$E$5="All Centres",B36=Dashboard!$E$5)),1,0) | U36: =IF(T36=1,COUNTIF($T$2:T36,1),"")
